2021-06-09 12:10:33,850 :: INFO :: ===================== Execution Start ==========================
2021-06-09 12:11:38,943 :: ERROR :: HTTPConnectionPool(host='169.254.169.254', port=80): Max retries exceeded with url: /opc/v2/identity/cert.pem (Caused by ConnectTimeoutError(<oci._vendor.urllib3.connection.HTTPConnection object at 0x7f76ca2f65f8>, 'Connection to 169.254.169.254 timed out. (connect timeout=10)'))
Traceback (most recent call last):
  File "/usr/local/lib/python3.6/site-packages/oci/_vendor/urllib3/connection.py", line 175, in _new_conn
    (self._dns_host, self.port), self.timeout, **extra_kw
  File "/usr/local/lib/python3.6/site-packages/oci/_vendor/urllib3/util/connection.py", line 101, in create_connection
    raise err
  File "/usr/local/lib/python3.6/site-packages/oci/_vendor/urllib3/util/connection.py", line 91, in create_connection
    sock.connect(sa)
socket.timeout: timed out

During handling of the above exception, another exception occurred:

Traceback (most recent call last):
  File "/usr/local/lib/python3.6/site-packages/oci/_vendor/urllib3/connectionpool.py", line 711, in urlopen
    chunked=chunked,
  File "/usr/local/lib/python3.6/site-packages/oci/_vendor/urllib3/connectionpool.py", line 399, in _make_request
    conn.request(method, url, **httplib_request_kw)
  File "/usr/local/lib/python3.6/site-packages/oci/_vendor/urllib3/connection.py", line 239, in request
    super(HTTPConnection, self).request(method, url, body=body, headers=headers)
  File "/usr/lib64/python3.6/http/client.py", line 1254, in request
    self._send_request(method, url, body, headers, encode_chunked)
  File "/usr/lib64/python3.6/http/client.py", line 1300, in _send_request
    self.endheaders(body, encode_chunked=encode_chunked)
  File "/usr/lib64/python3.6/http/client.py", line 1249, in endheaders
    self._send_output(message_body, encode_chunked=encode_chunked)
  File "/usr/lib64/python3.6/http/client.py", line 1036, in _send_output
    self.send(msg)
  File "/usr/lib64/python3.6/http/client.py", line 974, in send
    self.connect()
  File "/usr/local/lib/python3.6/site-packages/oci/_vendor/urllib3/connection.py", line 205, in connect
    conn = self._new_conn()
  File "/usr/local/lib/python3.6/site-packages/oci/_vendor/urllib3/connection.py", line 182, in _new_conn
    % (self.host, self.timeout),
oci._vendor.urllib3.exceptions.ConnectTimeoutError: (<oci._vendor.urllib3.connection.HTTPConnection object at 0x7f76ca2f65f8>, 'Connection to 169.254.169.254 timed out. (connect timeout=10)')

During handling of the above exception, another exception occurred:

Traceback (most recent call last):
  File "/usr/local/lib/python3.6/site-packages/oci/_vendor/requests/adapters.py", line 457, in send
    enforce_content_length=True
  File "/usr/local/lib/python3.6/site-packages/oci/_vendor/urllib3/connectionpool.py", line 761, in urlopen
    method, url, error=e, _pool=self, _stacktrace=sys.exc_info()[2]
  File "/usr/local/lib/python3.6/site-packages/oci/_vendor/urllib3/util/retry.py", line 579, in increment
    raise MaxRetryError(_pool, url, error or ResponseError(cause))
oci._vendor.urllib3.exceptions.MaxRetryError: HTTPConnectionPool(host='169.254.169.254', port=80): Max retries exceeded with url: /opc/v2/identity/cert.pem (Caused by ConnectTimeoutError(<oci._vendor.urllib3.connection.HTTPConnection object at 0x7f76ca2f65f8>, 'Connection to 169.254.169.254 timed out. (connect timeout=10)'))

During handling of the above exception, another exception occurred:

Traceback (most recent call last):
  File "./ocicron.py", line 151, in execute
    region=region)
  File "/media/datos/Preventa/desarrollo/iac/3kubeEjemplo/cencoAPIapagado/ocicron/ocicron_service.py", line 56, in __init__
    self.signer = oci.auth.signers.InstancePrincipalsSecurityTokenSigner()
  File "/usr/local/lib/python3.6/site-packages/oci/auth/signers/instance_principals_security_token_signer.py", line 69, in __init__
    headers=self.METADATA_AUTH_HEADERS)
  File "/usr/local/lib/python3.6/site-packages/oci/auth/certificate_retriever.py", line 111, in __init__
    self.refresh()
  File "/usr/local/lib/python3.6/site-packages/oci/auth/certificate_retriever.py", line 117, in refresh
    self.retry_strategy.make_retrying_call(self._refresh_inner)
  File "/usr/local/lib/python3.6/site-packages/oci/retry/retry.py", line 279, in make_retrying_call
    return func_ref(*func_args, **func_kwargs)
  File "/usr/local/lib/python3.6/site-packages/oci/auth/certificate_retriever.py", line 173, in _refresh_inner
    response = self.requests_session.get(self.cert_url, stream=True, timeout=(10, 60))
  File "/usr/local/lib/python3.6/site-packages/oci/_vendor/requests/sessions.py", line 560, in get
    return self.request('GET', url, **kwargs)
  File "/usr/local/lib/python3.6/site-packages/oci/_vendor/requests/sessions.py", line 547, in request
    resp = self.send(prep, **send_kwargs)
  File "/usr/local/lib/python3.6/site-packages/oci/_vendor/requests/sessions.py", line 660, in send
    r = adapter.send(request, **kwargs)
  File "/usr/local/lib/python3.6/site-packages/oci/_vendor/requests/adapters.py", line 512, in send
    raise ConnectTimeout(e, request=request)
oci._vendor.requests.exceptions.ConnectTimeout: HTTPConnectionPool(host='169.254.169.254', port=80): Max retries exceeded with url: /opc/v2/identity/cert.pem (Caused by ConnectTimeoutError(<oci._vendor.urllib3.connection.HTTPConnection object at 0x7f76ca2f65f8>, 'Connection to 169.254.169.254 timed out. (connect timeout=10)'))
2021-06-09 12:11:38,976 :: INFO :: Executing start action in Compute service, in region: us-ashburn-1 at: 11 and Weekend_stop: yes on 2 instances
